Workbook

Sheet Theory Component
C7: CIE for the theory component of Integrated Professional Core Courses (IPCC)
C9: Course | E9: Full Stack Development
C10: Course Code | E10: 22IS62
A12: Sl. No | B12: USN | C12: NAME | D12: IAT-1 (50) | E12: IAT-1 (Reduced to 30) (A) | F12: IAT-2 (50) | G12: IAT-2 (Reduced to 30) (B) | H12: IAT-3 (50) | I12: IAT-3 (Reduced to 30) (C) | J12: Average (A + B + C) / 3 (D) | K12: Quiz (30) | L12: Quiz (Reduced to 10) (E) | M12: AAT (10) (F) | N12: TOTAL G = (D + E + F) (50) | O12: G reduced to 30 (K) | P12: Lab Marks (L) (20) | Q12: Final Total (Theory (30) + Lab (20)) (50) | R12: TOTAL (Round up - Total 50) | S12: Attendance(40) | T12: Lab Att | U12: Total
A13: 1 | B13: 1DS22IS001 | C13: AADARSH KUMAR BATHWAL | D13: 45 | E13: =((D13*30)/50) -> 27 | F13: 46 | G13: =((F13*30)/50) -> 27.6 | H13: 40 | I13: =((H13*30)/50) -> 24 | J13: =((E13+G13+I13)/3) -> 26.2 | K13: 30 | L13: =((K13*10)/30) -> 10 | M13: 1 | N13: =SUM(J13,L13,M13) -> 37.2 | O13: =(N13/50)*30 -> 22.32 | P13: ='Lab Component'!K13 -> 19 | Q13: =(O13+P13) -> 41.32 | R13: =ROUNDUP(Q13,0) -> 42
A14: 2 | B14: 1DS22IS002 | C14: AADYA SHRIVASTAVA | D14: 1 | E14: =((D14*30)/50) -> 0.6 | F14: 1 | G14: =((F14*30)/50) -> 0.6 | H14: 1 | I14: =((H14*30)/50) -> 0.6 | J14: =((E14+G14+I14)/3) -> 0.6 | K14: 30 | L14: =((K14*10)/30) -> 10 | M14: 1 | N14: =SUM(J14,L14,M14) -> 11.6 | O14: =(N14/50)*30 -> 6.96 | P14: ='Lab Component'!K14 -> 20 | Q14: =(O14+P14) -> 26.96 | R14: =ROUNDUP(Q14,0) -> 27
A15: 3 | B15: 1DS22IS003 | C15: ADITHI S PAWAR | D15: 1 | E15: =((D15*30)/50) -> 0.6 | F15: 1 | G15: =((F15*30)/50) -> 0.6 | H15: 1 | I15: =((H15*30)/50) -> 0.6 | J15: =((E15+G15+I15)/3) -> 0.6 | K15: 30 | L15: =((K15*10)/30) -> 10 | M15: 1 | N15: =SUM(J15,L15,M15) -> 11.6 | O15: =(N15/50)*30 -> 6.96 | P15: ='Lab Component'!K15 -> 20 | Q15: =(O15+P15) -> 26.96 | R15: =ROUNDUP(Q15,0) -> 27
A16: 4 | B16: 1DS22IS004 | C16: ADITHYA N A | D16: 1 | E16: =((D16*30)/50) -> 0.6 | F16: 1 | G16: =((F16*30)/50) -> 0.6 | H16: 1 | I16: =((H16*30)/50) -> 0.6 | J16: =((E16+G16+I16)/3) -> 0.6 | K16: 28 | L16: =((K16*10)/30) -> 9.3333333 | M16: 1 | N16: =SUM(J16,L16,M16) -> 10.933333 | O16: =(N16/50)*30 -> 6.56 | P16: ='Lab Component'!K16 -> 20 | Q16: =(O16+P16) -> 26.56 | R16: =ROUNDUP(Q16,0) -> 27
A17: 5 | B17: 1DS22IS005 | C17: ADITYA ANAND | D17: 1 | E17: =((D17*30)/50) -> 0.6 | F17: 1 | G17: =((F17*30)/50) -> 0.6 | H17: 1 | I17: =((H17*30)/50) -> 0.6 | J17: =((E17+G17+I17)/3) -> 0.6 | K17: 30 | L17: =((K17*10)/30) -> 10 | M17: 1 | N17: =SUM(J17,L17,M17) -> 11.6 | O17: =(N17/50)*30 -> 6.96 | P17: ='Lab Component'!K17 -> 19 | Q17: =(O17+P17) -> 25.96 | R17: =ROUNDUP(Q17,0) -> 26
A18: 6 | B18: 1DS22IS006 | C18: ADITYA BHUSHAN | D18: 1 | E18: =((D18*30)/50) -> 0.6 | F18: 1 | G18: =((F18*30)/50) -> 0.6 | H18: 1 | I18: =((H18*30)/50) -> 0.6 | J18: =((E18+G18+I18)/3) -> 0.6 | K18: 30 | L18: =((K18*10)/30) -> 10 | M18: 1 | N18: =SUM(J18,L18,M18) -> 11.6 | O18: =(N18/50)*30 -> 6.96 | P18: ='Lab Component'!K18 -> 19 | Q18: =(O18+P18) -> 25.96 | R18: =ROUNDUP(Q18,0) -> 26
A19: 7 | B19: 1DS22IS007 | C19: ADITYA GANESH S | D19: 1 | E19: =((D19*30)/50) -> 0.6 | F19: 1 | G19: =((F19*30)/50) -> 0.6 | H19: 1 | I19: =((H19*30)/50) -> 0.6 | J19: =((E19+G19+I19)/3) -> 0.6 | K19: 30 | L19: =((K19*10)/30) -> 10 | M19: 1 | N19: =SUM(J19,L19,M19) -> 11.6 | O19: =(N19/50)*30 -> 6.96 | P19: ='Lab Component'!K19 -> 19 | Q19: =(O19+P19) -> 25.96 | R19: =ROUNDUP(Q19,0) -> 26
A20: 8 | B20: 1DS22IS008 | C20: ADITYA SINGH | D20: 1 | E20: =((D20*30)/50) -> 0.6 | F20: 1 | G20: =((F20*30)/50) -> 0.6 | H20: 1 | I20: =((H20*30)/50) -> 0.6 | J20: =((E20+G20+I20)/3) -> 0.6 | K20: 30 | L20: =((K20*10)/30) -> 10 | M20: 1 | N20: =SUM(J20,L20,M20) -> 11.6 | O20: =(N20/50)*30 -> 6.96 | P20: ='Lab Component'!K20 -> 20 | Q20: =(O20+P20) -> 26.96 | R20: =ROUNDUP(Q20,0) -> 27
A21: 9 | B21: 1DS22IS009 | C21: AKASH ARKA B | D21: 1 | E21: =((D21*30)/50) -> 0.6 | F21: 1 | G21: =((F21*30)/50) -> 0.6 | H21: 1 | I21: =((H21*30)/50) -> 0.6 | J21: =((E21+G21+I21)/3) -> 0.6 | K21: 30 | L21: =((K21*10)/30) -> 10 | M21: 1 | N21: =SUM(J21,L21,M21) -> 11.6 | O21: =(N21/50)*30 -> 6.96 | P21: ='Lab Component'!K21 -> 19 | Q21: =(O21+P21) -> 25.96 | R21: =ROUNDUP(Q21,0) -> 26
A22: 10 | B22: 1DS22IS010 | C22: AKASH G S | D22: 1 | E22: =((D22*30)/50) -> 0.6 | F22: 1 | G22: =((F22*30)/50) -> 0.6 | H22: 1 | I22: =((H22*30)/50) -> 0.6 | J22: =((E22+G22+I22)/3) -> 0.6 | K22: 30 | L22: =((K22*10)/30) -> 10 | M22: 1 | N22: =SUM(J22,L22,M22) -> 11.6 | O22: =(N22/50)*30 -> 6.96 | P22: ='Lab Component'!K22 -> 20 | Q22: =(O22+P22) -> 26.96 | R22: =ROUNDUP(Q22,0) -> 27
A23: 11 | B23: 1DS22IS011 | C23: AKASH GOYAL | D23: 1 | E23: =((D23*30)/50) -> 0.6 | F23: 1 | G23: =((F23*30)/50) -> 0.6 | H23: 1 | I23: =((H23*30)/50) -> 0.6 | J23: =((E23+G23+I23)/3) -> 0.6 | K23: 30 | L23: =((K23*10)/30) -> 10 | M23: 1 | N23: =SUM(J23,L23,M23) -> 11.6 | O23: =(N23/50)*30 -> 6.96 | P23: ='Lab Component'!K23 -> 19 | Q23: =(O23+P23) -> 25.96 | R23: =ROUNDUP(Q23,0) -> 26
A24: 12 | B24: 1DS22IS012 | C24: AKHAND PRATAP SINGH | D24: 1 | E24: =((D24*30)/50) -> 0.6 | F24: 1 | G24: =((F24*30)/50) -> 0.6 | H24: 1 | I24: =((H24*30)/50) -> 0.6 | J24: =((E24+G24+I24)/3) -> 0.6 | K24: 30 | L24: =((K24*10)/30) -> 10 | M24: 1 | N24: =SUM(J24,L24,M24) -> 11.6 | O24: =(N24/50)*30 -> 6.96 | P24: ='Lab Component'!K24 -> 19 | Q24: =(O24+P24) -> 25.96 | R24: =ROUNDUP(Q24,0) -> 26
... A31: 19 | B31: 1DS22IS019 | C31: ANANYA B A | D31: 1 | E31: =((D31*30)/50) -> 0.6 | F31: 1 | G31: =((F31*30)/50) -> 0.6 | H31: 1 | I31: =((H31*30)/50) -> 0.6 | J31: =((E31+G31+I31)/3) -> 0.6 | K31: 30 | L31: =((K31*10)/30) -> 10 | M31: 1 | N31: =SUM(J31,L31,M31) -> 11.6 | O31: =(N31/50)*30 -> 6.96 | P31: ='Lab Component'!K31 -> 20 | Q31: =(O31+P31) -> 26.96 | R31: =ROUNDUP(Q31,0) -> 27
A32: 20 | B32: 1DS22IS020 | C32: ANANYA OLEKAR | D32: 1 | E32: =((D32*30)/50) -> 0.6 | F32: 1 | G32: =((F32*30)/50) -> 0.6 | H32: 1 | I32: =((H32*30)/50) -> 0.6 | J32: =((E32+G32+I32)/3) -> 0.6 | L32: =((K32*10)/30) -> 0 | M32: 1 | N32: =SUM(J32,L32,M32) -> 1.6 | O32: =(N32/50)*30 -> 0.96 | P32: ='Lab Component'!K32 -> 19 | Q32: =(O32+P32) -> 19.96 | R32: =ROUNDUP(Q32,0) -> 20
A33: 21 | B33: 1DS22IS021 | C33: ANANYA PRAMOD | D33: 1 | E33: =((D33*30)/50) -> 0.6 | F33: 1 | G33: =((F33*30)/50) -> 0.6 | H33: 1 | I33: =((H33*30)/50) -> 0.6 | J33: =((E33+G33+I33)/3) -> 0.6 | K33: 30 | L33: =((K33*10)/30) -> 10 | M33: 1 | N33: =SUM(J33,L33,M33) -> 11.6 | O33: =(N33/50)*30 -> 6.96 | P33: ='Lab Component'!K33 -> 20 | Q33: =(O33+P33) -> 26.96 | R33: =ROUNDUP(Q33,0) -> 27
A34: 22 | B34: 1DS22IS022 | C34: ANEESH M KASHYAP | D34: 1 | E34: =((D34*30)/50) -> 0.6 | F34: 1 | G34: 4 | H34: 1 | I34: =((H34*30)/50) -> 0.6 | J34: =((E34+G34+I34)/3) -> 1.7333333 | K34: 30 | L34: =((K34*10)/30) -> 10 | M34: 1 | N34: =SUM(J34,L34,M34) -> 12.733333 | O34: =(N34/50)*30 -> 7.64 | P34: ='Lab Component'!K34 -> 19 | Q34: =(O34+P34) -> 26.64 | R34: =ROUNDUP(Q34,0) -> 27
A35: 23 | B35: 1DS22IS023 | C35: ANUBHAB KAR | D35: 1 | E35: =((D35*30)/50) -> 0.6 | F35: 1 | G35: =((F35*30)/50) -> 0.6 | H35: 1 | I35: =((H35*30)/50) -> 0.6 | J35: =((E35+G35+I35)/3) -> 0.6 | K35: 30 | L35: =((K35*10)/30) -> 10 | M35: 1 | N35: =SUM(J35,L35,M35) -> 11.6 | O35: =(N35/50)*30 -> 6.96 | P35: ='Lab Component'!K35 -> 19 | Q35: =(O35+P35) -> 25.96 | R35: =ROUNDUP(Q35,0) -> 26
A36: 24 | B36: 1DS22IS024 | C36: ANUPAM | D36: 1 | E36: =((D36*30)/50) -> 0.6 | F36: 1 | G36: =((F36*30)/50) -> 0.6 | H36: 1 | I36: =((H36*30)/50) -> 0.6 | J36: =((E36+G36+I36)/3) -> 0.6 | K36: 30 | L36: =((K36*10)/30) -> 10 | M36: 1 | N36: =SUM(J36,L36,M36) -> 11.6 | O36: =(N36/50)*30 -> 6.96 | P36: ='Lab Component'!K36 -> 19 | Q36: =(O36+P36) -> 25.96 | R36: =ROUNDUP(Q36,0) -> 26
A37: 25 | B37: 1DS22IS025 | C37: ANUSHA R | D37: 1 | E37: =((D37*30)/50) -> 0.6 | F37: 1 | G37: =((F37*30)/50) -> 0.6 | H37: 1 | I37: =((H37*30)/50) -> 0.6 | J37: =((E37+G37+I37)/3) -> 0.6 | K37: 30 | L37: =((K37*10)/30) -> 10 | M37: 1 | N37: =SUM(J37,L37,M37) -> 11.6 | O37: =(N37/50)*30 -> 6.96 | P37: ='Lab Component'!K37 -> 20 | Q37: =(O37+P37) -> 26.96 | R37: =ROUNDUP(Q37,0) -> 27
A38: 26 | B38: 1DS22IS026 | C38: ARUN B Y | D38: 1 | E38: =((D38*30)/50) -> 0.6 | F38: 1 | G38: =((F38*30)/50) -> 0.6 | H38: 1 | I38: =((H38*30)/50) -> 0.6 | J38: =((E38+G38+I38)/3) -> 0.6 | K38: 30 | L38: =((K38*10)/30) -> 10 | M38: 1 | N38: =SUM(J38,L38,M38) -> 11.6 | O38: =(N38/50)*30 -> 6.96 | P38: ='Lab Component'!K38 -> 20 | Q38: =(O38+P38) -> 26.96 | R38: =ROUNDUP(Q38,0) -> 27
A39: 27 | B39: 1DS22IS027 | C39: ASHUTOSH KUMAR | D39: 1 | E39: =((D39*30)/50) -> 0.6 | F39: 1 | G39: =((F39*30)/50) -> 0.6 | H39: 1 | I39: =((H39*30)/50) -> 0.6 | J39: =((E39+G39+I39)/3) -> 0.6 | K39: 30 | L39: =((K39*10)/30) -> 10 | M39: 1 | N39: =SUM(J39,L39,M39) -> 11.6 | O39: =(N39/50)*30 -> 6.96 | P39: ='Lab Component'!K39 -> 19 | Q39: =(O39+P39) -> 25.96 | R39: =ROUNDUP(Q39,0) -> 26
A40: 28 | B40: 1DS22IS028 | C40: ASHWIN S | D40: 1 | E40: =((D40*30)/50) -> 0.6 | F40: 1 | G40: =((F40*30)/50) -> 0.6 | H40: 1 | I40: =((H40*30)/50) -> 0.6 | J40: =((E40+G40+I40)/3) -> 0.6 | K40: 30 | L40: =((K40*10)/30) -> 10 | M40: 1 | N40: =SUM(J40,L40,M40) -> 11.6 | O40: =(N40/50)*30 -> 6.96 | P40: ='Lab Component'!K40 -> 20 | Q40: =(O40+P40) -> 26.96 | R40: =ROUNDUP(Q40,0) -> 27
A41: 29 | B41: 1DS22IS029 | C41: ATHARVA KUMAR | D41: 1 | E41: =((D41*30)/50) -> 0.6 | F41: 1 | G41: =((F41*30)/50) -> 0.6 | H41: 1 | I41: =((H41*30)/50) -> 0.6 | J41: =((E41+G41+I41)/3) -> 0.6 | K41: 30 | L41: =((K41*10)/30) -> 10 | M41: 1 | N41: =SUM(J41,L41,M41) -> 11.6 | O41: =(N41/50)*30 -> 6.96 | P41: ='Lab Component'!K41 -> 20 | Q41: =(O41+P41) -> 26.96 | R41: =ROUNDUP(Q41,0) -> 27
A42: 30 | B42: 1DS22IS030 | C42: AVANTIKA KESARWANI | D42: 1 | E42: =((D42*30)/50) -> 0.6 | F42: 1 | G42: =((F42*30)/50) -> 0.6 | H42: 1 | I42: =((H42*30)/50) -> 0.6 | J42: =((E42+G42+I42)/3) -> 0.6 | K42: 30 | L42: =((K42*10)/30) -> 10 | M42: 1 | N42: =SUM(J42,L42,M42) -> 11.6 | O42: =(N42/50)*30 -> 6.96 | P42: ='Lab Component'!K42 -> 20 | Q42: =(O42+P42) -> 26.96 | R42: =ROUNDUP(Q42,0) -> 27
A43: 31 | B43: 1DS22IS031 | C43: AYUSH RAJ | D43: 1 | E43: =((D43*30)/50) -> 0.6 | F43: 1 | G43: =((F43*30)/50) -> 0.6 | H43: 1 | I43: =((H43*30)/50) -> 0.6 | J43: =((E43+G43+I43)/3) -> 0.6 | K43: 30 | L43: =((K43*10)/30) -> 10 | M43: 1 | N43: =SUM(J43,L43,M43) -> 11.6 | O43: =(N43/50)*30 -> 6.96 | P43: ='Lab Component'!K43 -> 19 | Q43: =(O43+P43) -> 25.96 | R43: =ROUNDUP(Q43,0) -> 26
A44: 32 | B44: 1DS22IS032 | C44: BHARATH N J | D44: 1 | E44: =((D44*30)/50) -> 0.6 | F44: 1 | G44: =((F44*30)/50) -> 0.6 | H44: 1 | I44: =((H44*30)/50) -> 0.6 | J44: =((E44+G44+I44)/3) -> 0.6 | K44: 30 | L44: =((K44*10)/30) -> 10 | M44: 1 | N44: =SUM(J44,L44,M44) -> 11.6 | O44: =(N44/50)*30 -> 6.96 | P44: ='Lab Component'!K44 -> 20 | Q44: =(O44+P44) -> 26.96 | R44: =ROUNDUP(Q44,0) -> 27
A45: 33 | B45: 1DS22IS033 | C45: BHAVANA S | D45: 1 | E45: =((D45*30)/50) -> 0.6 | F45: 1 | G45: =((F45*30)/50) -> 0.6 | H45: 1 | I45: =((H45*30)/50) -> 0.6 | J45: =((E45+G45+I45)/3) -> 0.6 | K45: 30 | L45: =((K45*10)/30) -> 10 | M45: 1 | N45: =SUM(J45,L45,M45) -> 11.6 | O45: =(N45/50)*30 -> 6.96 | P45: ='Lab Component'!K45 -> 19 | Q45: =(O45+P45) -> 25.96 | R45: =ROUNDUP(Q45,0) -> 26
A46: 34 | B46: 1DS22IS034 | C46: BHAVANI C P | D46: 1 | E46: =((D46*30)/50) -> 0.6 | F46: 1 | G46: =((F46*30)/50) -> 0.6 | H46: 1 | I46: =((H46*30)/50) -> 0.6 | J46: =((E46+G46+I46)/3) -> 0.6 | K46: 30 | L46: =((K46*10)/30) -> 10 | M46: 1 | N46: =SUM(J46,L46,M46) -> 11.6 | O46: =(N46/50)*30 -> 6.96 | P46: ='Lab Component'!K46 -> 20 | Q46: =(O46+P46) -> 26.96 | R46: =ROUNDUP(Q46,0) -> 27
... A76: 64 | B76: 1DS22IS064 | C76: JISHNU MANJUNATH M | D76: 1 | E76: =((D76*30)/50) -> 0.6 | F76: 1 | G76: =((F76*30)/50) -> 0.6 | H76: 1 | I76: =((H76*30)/50) -> 0.6 | J76: =((E76+G76+I76)/3) -> 0.6 | K76: 30 | L76: =((K76*10)/30) -> 10 | M76: 1 | N76: =SUM(J76,L76,M76) -> 11.6 | O76: =(N76/50)*30 -> 6.96 | P76: ='Lab Component'!K76 -> 19 | Q76: =(O76+P76) -> 25.96 | R76: =ROUNDUP(Q76,0) -> 26
A77: 65 | B77: 1DS22IS065 | C77: K N RISHAB PURANIKA | D77: 43 | E77: =((D77*30)/50) -> 25.8 | F77: 44 | G77: =((F77*30)/50) -> 26.4 | H77: 46 | I77: =((H77*30)/50) -> 27.6 | J77: =((E77+G77+I77)/3) -> 26.6 | K77: 30 | L77: =((K77*10)/30) -> 10 | M77: 10 | N77: =SUM(J77,L77,M77) -> 46.6 | O77: =(N77/50)*30 -> 27.96 | P77: ='Lab Component'!K77 -> 20 | Q77: =(O77+P77) -> 47.96 | R77: =ROUNDUP(Q77,0) -> 48 | S77: 39
A78: 66 | B78: 1DS22IS066 | C78: KAVYASHREE T | D78: 48 | E78: =((D78*30)/50) -> 28.8 | F78: 50 | G78: =((F78*30)/50) -> 30 | H78: 49 | I78: =((H78*30)/50) -> 29.4 | J78: =((E78+G78+I78)/3) -> 29.4 | K78: 30 | L78: =((K78*10)/30) -> 10 | M78: 10 | N78: =SUM(J78,L78,M78) -> 49.4 | O78: =(N78/50)*30 -> 29.64 | P78: ='Lab Component'!K78 -> 20 | Q78: =(O78+P78) -> 49.64 | R78: =ROUNDUP(Q78,0) -> 50 | S78: 39
A79: 67 | B79: 1DS22IS067 | C79: KEERTHI B | D79: 49 | E79: =((D79*30)/50) -> 29.4 | F79: 50 | G79: =((F79*30)/50) -> 30 | H79: 48 | I79: =((H79*30)/50) -> 28.8 | J79: =((E79+G79+I79)/3) -> 29.4 | K79: 30 | L79: =((K79*10)/30) -> 10 | M79: 8.5 | N79: =SUM(J79,L79,M79) -> 47.9 | O79: =(N79/50)*30 -> 28.74 | P79: ='Lab Component'!K79 -> 20 | Q79: =(O79+P79) -> 48.74 | R79: =ROUNDUP(Q79,0) -> 49 | S79: 39
A80: 68 | B80: 1DS22IS068 | C80: KISHOR KALYANI WADEYAR | D80: 50 | E80: =((D80*30)/50) -> 30 | F80: 47 | G80: =((F80*30)/50) -> 28.2 | H80: 47 | I80: =((H80*30)/50) -> 28.2 | J80: =((E80+G80+I80)/3) -> 28.8 | K80: 30 | L80: =((K80*10)/30) -> 10 | M80: 10 | N80: =SUM(J80,L80,M80) -> 48.8 | O80: =(N80/50)*30 -> 29.28 | P80: ='Lab Component'!K80 -> 19 | Q80: =(O80+P80) -> 48.28 | R80: =ROUNDUP(Q80,0) -> 49 | S80: 37
A81: 69 | B81: 1DS22IS069 | C81: KUSHAL NAYAK S P | D81: 42 | E81: =((D81*30)/50) -> 25.2 | F81: 50 | G81: =((F81*30)/50) -> 30 | H81: 44 | I81: =((H81*30)/50) -> 26.4 | J81: =((E81+G81+I81)/3) -> 27.2 | K81: 30 | L81: =((K81*10)/30) -> 10 | M81: 9.5 | N81: =SUM(J81,L81,M81) -> 46.7 | O81: =(N81/50)*30 -> 28.02 | P81: ='Lab Component'!K81 -> 19 | Q81: =(O81+P81) -> 47.02 | R81: =ROUNDUP(Q81,0) -> 48 | S81: 37
A82: 70 | B82: 1DS22IS070 | C82: LAISIRI N M | D82: 46 | E82: =((D82*30)/50) -> 27.6 | F82: 50 | G82: =((F82*30)/50) -> 30 | H82: 50 | I82: =((H82*30)/50) -> 30 | J82: =((E82+G82+I82)/3) -> 29.2 | K82: 30 | L82: =((K82*10)/30) -> 10 | M82: 10 | N82: =SUM(J82,L82,M82) -> 49.2 | O82: =(N82/50)*30 -> 29.52 | P82: ='Lab Component'!K82 -> 12 | Q82: =(O82+P82) -> 41.52 | R82: =ROUNDUP(Q82,0) -> 42 | S82: 37
A83: 71 | B83: 1DS22IS071 | C83: LANKESH N C D | D83: 40 | E83: =((D83*30)/50) -> 24 | F83: 27 | G83: =((F83*30)/50) -> 16.2 | H83: 43 | I83: =((H83*30)/50) -> 25.8 | J83: =((E83+G83+I83)/3) -> 22 | K83: 30 | L83: =((K83*10)/30) -> 10 | M83: 10 | N83: =SUM(J83,L83,M83) -> 42 | O83: =(N83/50)*30 -> 25.2 | P83: ='Lab Component'!K83 -> 19 | Q83: =(O83+P83) -> 44.2 | R83: =ROUNDUP(Q83,0) -> 45 | S83: 38
...

Sheet Theory Component_Lab_modified
C7: CIE for the theory component of Integrated Professional Core Courses (IPCC)
C9: Course | E9: Full Stack Development
C10: Course Code | E10: 22IS62
A12: Sl. No | B12: USN | C12: NAME | D12: IAT-1 (50) | E12: IAT-1 (Reduced to 30) (A) | F12: IAT-2 (50) | G12: IAT-2 (Reduced to 30) (B) | H12: IAT-3 (50) | I12: IAT-3 (Reduced to 30) (C) | J12: Average (A + B + C) / 3 (D) | K12: Quiz (30) | L12: Quiz (Reduced to 10) (E) | M12: AAT (10) (F) | N12: Total Quiz | O12: TOTAL G = (D + E + F) (50) | P12: G reduced to 30 (K) | Q12: Lab Marks (L) (20) | R12: Final Total (Theory (30) + Lab (20)) (50) | S12: TOTAL (Round up - Total 50) | T12: Attendance(40) | U12: Lab Att | V12: Total
A13: 1 | B13: 1DS22IS001 | C13: AADARSH KUMAR BATHWAL | D13: 45 | E13: =((D13*30)/50) -> 27 | F13: 46 | G13: =((F13*30)/50) -> 27.6 | H13: 40 | I13: =((H13*30)/50) -> 24 | J13: =((E13+G13+I13)/3) -> 26.2 | K13: 30 | L13: =((K13*10)/30) -> 10 | M13: 1 | O13: =SUM(J13,L13,M13) -> 37.2 | P13: =(O13/50)*30 -> 22.32 | Q13: ='Lab Component'!K13 -> 19 | R13: =(P13+Q13) -> 41.32 | S13: =ROUNDUP(R13,0) -> 42
A14: 2 | B14: 1DS22IS002 | C14: AADYA SHRIVASTAVA | D14: 1 | E14: =((D14*30)/50) -> 0.6 | F14: 1 | G14: =((F14*30)/50) -> 0.6 | H14: 1 | I14: =((H14*30)/50) -> 0.6 | J14: =((E14+G14+I14)/3) -> 0.6 | K14: 30 | L14: =((K14*10)/30) -> 10 | M14: 1 | O14: =SUM(J14,L14,M14) -> 11.6 | P14: =(O14/50)*30 -> 6.96 | Q14: ='Lab Component'!K14 -> 20 | R14: =(P14+Q14) -> 26.96 | S14: =ROUNDUP(R14,0) -> 27
A15: 3 | B15: 1DS22IS003 | C15: ADITHI S PAWAR | D15: 1 | E15: =((D15*30)/50) -> 0.6 | F15: 1 | G15: =((F15*30)/50) -> 0.6 | H15: 1 | I15: =((H15*30)/50) -> 0.6 | J15: =((E15+G15+I15)/3) -> 0.6 | K15: 30 | L15: =((K15*10)/30) -> 10 | M15: 1 | O15: =SUM(J15,L15,M15) -> 11.6 | P15: =(O15/50)*30 -> 6.96 | Q15: ='Lab Component'!K15 -> 20 | R15: =(P15+Q15) -> 26.96 | S15: =ROUNDUP(R15,0) -> 27
A16: 4 | B16: 1DS22IS004 | C16: ADITHYA N A | D16: 1 | E16: =((D16*30)/50) -> 0.6 | F16: 1 | G16: =((F16*30)/50) -> 0.6 | H16: 1 | I16: =((H16*30)/50) -> 0.6 | J16: =((E16+G16+I16)/3) -> 0.6 | K16: 28 | L16: =((K16*10)/30) -> 9.3333333 | M16: 1 | O16: =SUM(J16,L16,M16) -> 10.933333 | P16: =(O16/50)*30 -> 6.56 | Q16: ='Lab Component'!K16 -> 20 | R16: =(P16+Q16) -> 26.56 | S16: =ROUNDUP(R16,0) -> 27
A17: 5 | B17: 1DS22IS005 | C17: ADITYA ANAND | D17: 1 | E17: =((D17*30)/50) -> 0.6 | F17: 1 | G17: =((F17*30)/50) -> 0.6 | H17: 1 | I17: =((H17*30)/50) -> 0.6 | J17: =((E17+G17+I17)/3) -> 0.6 | K17: 30 | L17: =((K17*10)/30) -> 10 | M17: 1 | O17: =SUM(J17,L17,M17) -> 11.6 | P17: =(O17/50)*30 -> 6.96 | Q17: ='Lab Component'!K17 -> 19 | R17: =(P17+Q17) -> 25.96 | S17: =ROUNDUP(R17,0) -> 26
A18: 6 | B18: 1DS22IS006 | C18: ADITYA BHUSHAN | D18: 1 | E18: =((D18*30)/50) -> 0.6 | F18: 1 | G18: =((F18*30)/50) -> 0.6 | H18: 1 | I18: =((H18*30)/50) -> 0.6 | J18: =((E18+G18+I18)/3) -> 0.6 | K18: 30 | L18: =((K18*10)/30) -> 10 | M18: 1 | O18: =SUM(J18,L18,M18) -> 11.6 | P18: =(O18/50)*30 -> 6.96 | Q18: ='Lab Component'!K18 -> 19 | R18: =(P18+Q18) -> 25.96 | S18: =ROUNDUP(R18,0) -> 26
A19: 7 | B19: 1DS22IS007 | C19: ADITYA GANESH S | D19: 1 | E19: =((D19*30)/50) -> 0.6 | F19: 1 | G19: =((F19*30)/50) -> 0.6 | H19: 1 | I19: =((H19*30)/50) -> 0.6 | J19: =((E19+G19+I19)/3) -> 0.6 | K19: 30 | L19: =((K19*10)/30) -> 10 | M19: 1 | O19: =SUM(J19,L19,M19) -> 11.6 | P19: =(O19/50)*30 -> 6.96 | Q19: ='Lab Component'!K19 -> 19 | R19: =(P19+Q19) -> 25.96 | S19: =ROUNDUP(R19,0) -> 26
A20: 8 | B20: 1DS22IS008 | C20: ADITYA SINGH | D20: 1 | E20: =((D20*30)/50) -> 0.6 | F20: 1 | G20: =((F20*30)/50) -> 0.6 | H20: 1 | I20: =((H20*30)/50) -> 0.6 | J20: =((E20+G20+I20)/3) -> 0.6 | K20: 30 | L20: =((K20*10)/30) -> 10 | M20: 1 | O20: =SUM(J20,L20,M20) -> 11.6 | P20: =(O20/50)*30 -> 6.96 | Q20: ='Lab Component'!K20 -> 20 | R20: =(P20+Q20) -> 26.96 | S20: =ROUNDUP(R20,0) -> 27
A21: 9 | B21: 1DS22IS009 | C21: AKASH ARKA B | D21: 1 | E21: =((D21*30)/50) -> 0.6 | F21: 1 | G21: =((F21*30)/50) -> 0.6 | H21: 1 | I21: =((H21*30)/50) -> 0.6 | J21: =((E21+G21+I21)/3) -> 0.6 | K21: 30 | L21: =((K21*10)/30) -> 10 | M21: 1 | O21: =SUM(J21,L21,M21) -> 11.6 | P21: =(O21/50)*30 -> 6.96 | Q21: ='Lab Component'!K21 -> 19 | R21: =(P21+Q21) -> 25.96 | S21: =ROUNDUP(R21,0) -> 26
A22: 10 | B22: 1DS22IS010 | C22: AKASH G S | D22: 1 | E22: =((D22*30)/50) -> 0.6 | F22: 1 | G22: =((F22*30)/50) -> 0.6 | H22: 1 | I22: =((H22*30)/50) -> 0.6 | J22: =((E22+G22+I22)/3) -> 0.6 | K22: 30 | L22: =((K22*10)/30) -> 10 | M22: 1 | O22: =SUM(J22,L22,M22) -> 11.6 | P22: =(O22/50)*30 -> 6.96 | Q22: ='Lab Component'!K22 -> 20 | R22: =(P22+Q22) -> 26.96 | S22: =ROUNDUP(R22,0) -> 27
A23: 11 | B23: 1DS22IS011 | C23: AKASH GOYAL | D23: 1 | E23: =((D23*30)/50) -> 0.6 | F23: 1 | G23: =((F23*30)/50) -> 0.6 | H23: 1 | I23: =((H23*30)/50) -> 0.6 | J23: =((E23+G23+I23)/3) -> 0.6 | K23: 30 | L23: =((K23*10)/30) -> 10 | M23: 1 | O23: =SUM(J23,L23,M23) -> 11.6 | P23: =(O23/50)*30 -> 6.96 | Q23: ='Lab Component'!K23 -> 19 | R23: =(P23+Q23) -> 25.96 | S23: =ROUNDUP(R23,0) -> 26
A24: 12 | B24: 1DS22IS012 | C24: AKHAND PRATAP SINGH | D24: 1 | E24: =((D24*30)/50) -> 0.6 | F24: 1 | G24: =((F24*30)/50) -> 0.6 | H24: 1 | I24: =((H24*30)/50) -> 0.6 | J24: =((E24+G24+I24)/3) -> 0.6 | K24: 30 | L24: =((K24*10)/30) -> 10 | M24: 1 | O24: =SUM(J24,L24,M24) -> 11.6 | P24: =(O24/50)*30 -> 6.96 | Q24: ='Lab Component'!K24 -> 19 | R24: =(P24+Q24) -> 25.96 | S24: =ROUNDUP(R24,0) -> 26
... A31: 19 | B31: 1DS22IS019 | C31: ANANYA B A | D31: 1 | E31: =((D31*30)/50) -> 0.6 | F31: 1 | G31: =((F31*30)/50) -> 0.6 | H31: 1 | I31: =((H31*30)/50) -> 0.6 | J31: =((E31+G31+I31)/3) -> 0.6 | K31: 30 | L31: =((K31*10)/30) -> 10 | M31: 1 | O31: =SUM(J31,L31,M31) -> 11.6 | P31: =(O31/50)*30 -> 6.96 | Q31: ='Lab Component'!K31 -> 20 | R31: =(P31+Q31) -> 26.96 | S31: =ROUNDUP(R31,0) -> 27
A32: 20 | B32: 1DS22IS020 | C32: ANANYA OLEKAR | D32: 1 | E32: =((D32*30)/50) -> 0.6 | F32: 1 | G32: =((F32*30)/50) -> 0.6 | H32: 1 | I32: =((H32*30)/50) -> 0.6 | J32: =((E32+G32+I32)/3) -> 0.6 | L32: =((K32*10)/30) -> 0 | M32: 1 | O32: =SUM(J32,L32,M32) -> 1.6 | P32: =(O32/50)*30 -> 0.96 | Q32: ='Lab Component'!K32 -> 19 | R32: =(P32+Q32) -> 19.96 | S32: =ROUNDUP(R32,0) -> 20
A33: 21 | B33: 1DS22IS021 | C33: ANANYA PRAMOD | D33: 1 | E33: =((D33*30)/50) -> 0.6 | F33: 1 | G33: =((F33*30)/50) -> 0.6 | H33: 1 | I33: =((H33*30)/50) -> 0.6 | J33: =((E33+G33+I33)/3) -> 0.6 | K33: 30 | L33: =((K33*10)/30) -> 10 | M33: 1 | O33: =SUM(J33,L33,M33) -> 11.6 | P33: =(O33/50)*30 -> 6.96 | Q33: ='Lab Component'!K33 -> 20 | R33: =(P33+Q33) -> 26.96 | S33: =ROUNDUP(R33,0) -> 27
A34: 22 | B34: 1DS22IS022 | C34: ANEESH M KASHYAP | D34: 1 | E34: =((D34*30)/50) -> 0.6 | F34: 1 | G34: 4 | H34: 1 | I34: =((H34*30)/50) -> 0.6 | J34: =((E34+G34+I34)/3) -> 1.7333333 | K34: 30 | L34: =((K34*10)/30) -> 10 | M34: 1 | O34: =SUM(J34,L34,M34) -> 12.733333 | P34: =(O34/50)*30 -> 7.64 | Q34: ='Lab Component'!K34 -> 19 | R34: =(P34+Q34) -> 26.64 | S34: =ROUNDUP(R34,0) -> 27
A35: 23 | B35: 1DS22IS023 | C35: ANUBHAB KAR | D35: 1 | E35: =((D35*30)/50) -> 0.6 | F35: 1 | G35: =((F35*30)/50) -> 0.6 | H35: 1 | I35: =((H35*30)/50) -> 0.6 | J35: =((E35+G35+I35)/3) -> 0.6 | K35: 30 | L35: =((K35*10)/30) -> 10 | M35: 1 | O35: =SUM(J35,L35,M35) -> 11.6 | P35: =(O35/50)*30 -> 6.96 | Q35: ='Lab Component'!K35 -> 19 | R35: =(P35+Q35) -> 25.96 | S35: =ROUNDUP(R35,0) -> 26
A36: 24 | B36: 1DS22IS024 | C36: ANUPAM | D36: 1 | E36: =((D36*30)/50) -> 0.6 | F36: 1 | G36: =((F36*30)/50) -> 0.6 | H36: 1 | I36: =((H36*30)/50) -> 0.6 | J36: =((E36+G36+I36)/3) -> 0.6 | K36: 30 | L36: =((K36*10)/30) -> 10 | M36: 1 | O36: =SUM(J36,L36,M36) -> 11.6 | P36: =(O36/50)*30 -> 6.96 | Q36: ='Lab Component'!K36 -> 19 | R36: =(P36+Q36) -> 25.96 | S36: =ROUNDUP(R36,0) -> 26
A37: 25 | B37: 1DS22IS025 | C37: ANUSHA R | D37: 1 | E37: =((D37*30)/50) -> 0.6 | F37: 1 | G37: =((F37*30)/50) -> 0.6 | H37: 1 | I37: =((H37*30)/50) -> 0.6 | J37: =((E37+G37+I37)/3) -> 0.6 | K37: 30 | L37: =((K37*10)/30) -> 10 | M37: 1 | O37: =SUM(J37,L37,M37) -> 11.6 | P37: =(O37/50)*30 -> 6.96 | Q37: ='Lab Component'!K37 -> 20 | R37: =(P37+Q37) -> 26.96 | S37: =ROUNDUP(R37,0) -> 27
A38: 26 | B38: 1DS22IS026 | C38: ARUN B Y | D38: 1 | E38: =((D38*30)/50) -> 0.6 | F38: 1 | G38: =((F38*30)/50) -> 0.6 | H38: 1 | I38: =((H38*30)/50) -> 0.6 | J38: =((E38+G38+I38)/3) -> 0.6 | K38: 30 | L38: =((K38*10)/30) -> 10 | M38: 1 | O38: =SUM(J38,L38,M38) -> 11.6 | P38: =(O38/50)*30 -> 6.96 | Q38: ='Lab Component'!K38 -> 20 | R38: =(P38+Q38) -> 26.96 | S38: =ROUNDUP(R38,0) -> 27
A39: 27 | B39: 1DS22IS027 | C39: ASHUTOSH KUMAR | D39: 1 | E39: =((D39*30)/50) -> 0.6 | F39: 1 | G39: =((F39*30)/50) -> 0.6 | H39: 1 | I39: =((H39*30)/50) -> 0.6 | J39: =((E39+G39+I39)/3) -> 0.6 | K39: 30 | L39: =((K39*10)/30) -> 10 | M39: 1 | O39: =SUM(J39,L39,M39) -> 11.6 | P39: =(O39/50)*30 -> 6.96 | Q39: ='Lab Component'!K39 -> 19 | R39: =(P39+Q39) -> 25.96 | S39: =ROUNDUP(R39,0) -> 26
A40: 28 | B40: 1DS22IS028 | C40: ASHWIN S | D40: 1 | E40: =((D40*30)/50) -> 0.6 | F40: 1 | G40: =((F40*30)/50) -> 0.6 | H40: 1 | I40: =((H40*30)/50) -> 0.6 | J40: =((E40+G40+I40)/3) -> 0.6 | K40: 30 | L40: =((K40*10)/30) -> 10 | M40: 1 | O40: =SUM(J40,L40,M40) -> 11.6 | P40: =(O40/50)*30 -> 6.96 | Q40: ='Lab Component'!K40 -> 20 | R40: =(P40+Q40) -> 26.96 | S40: =ROUNDUP(R40,0) -> 27
A41: 29 | B41: 1DS22IS029 | C41: ATHARVA KUMAR | D41: 1 | E41: =((D41*30)/50) -> 0.6 | F41: 1 | G41: =((F41*30)/50) -> 0.6 | H41: 1 | I41: =((H41*30)/50) -> 0.6 | J41: =((E41+G41+I41)/3) -> 0.6 | K41: 30 | L41: =((K41*10)/30) -> 10 | M41: 1 | O41: =SUM(J41,L41,M41) -> 11.6 | P41: =(O41/50)*30 -> 6.96 | Q41: ='Lab Component'!K41 -> 20 | R41: =(P41+Q41) -> 26.96 | S41: =ROUNDUP(R41,0) -> 27
A42: 30 | B42: 1DS22IS030 | C42: AVANTIKA KESARWANI | D42: 1 | E42: =((D42*30)/50) -> 0.6 | F42: 1 | G42: =((F42*30)/50) -> 0.6 | H42: 1 | I42: =((H42*30)/50) -> 0.6 | J42: =((E42+G42+I42)/3) -> 0.6 | K42: 30 | L42: =((K42*10)/30) -> 10 | M42: 1 | O42: =SUM(J42,L42,M42) -> 11.6 | P42: =(O42/50)*30 -> 6.96 | Q42: ='Lab Component'!K42 -> 20 | R42: =(P42+Q42) -> 26.96 | S42: =ROUNDUP(R42,0) -> 27
A43: 31 | B43: 1DS22IS031 | C43: AYUSH RAJ | D43: 1 | E43: =((D43*30)/50) -> 0.6 | F43: 1 | G43: =((F43*30)/50) -> 0.6 | H43: 1 | I43: =((H43*30)/50) -> 0.6 | J43: =((E43+G43+I43)/3) -> 0.6 | K43: 30 | L43: =((K43*10)/30) -> 10 | M43: 1 | O43: =SUM(J43,L43,M43) -> 11.6 | P43: =(O43/50)*30 -> 6.96 | Q43: ='Lab Component'!K43 -> 19 | R43: =(P43+Q43) -> 25.96 | S43: =ROUNDUP(R43,0) -> 26
A44: 32 | B44: 1DS22IS032 | C44: BHARATH N J | D44: 1 | E44: =((D44*30)/50) -> 0.6 | F44: 1 | G44: =((F44*30)/50) -> 0.6 | H44: 1 | I44: =((H44*30)/50) -> 0.6 | J44: =((E44+G44+I44)/3) -> 0.6 | K44: 30 | L44: =((K44*10)/30) -> 10 | M44: 1 | O44: =SUM(J44,L44,M44) -> 11.6 | P44: =(O44/50)*30 -> 6.96 | Q44: ='Lab Component'!K44 -> 20 | R44: =(P44+Q44) -> 26.96 | S44: =ROUNDUP(R44,0) -> 27
A45: 33 | B45: 1DS22IS033 | C45: BHAVANA S | D45: 1 | E45: =((D45*30)/50) -> 0.6 | F45: 1 | G45: =((F45*30)/50) -> 0.6 | H45: 1 | I45: =((H45*30)/50) -> 0.6 | J45: =((E45+G45+I45)/3) -> 0.6 | K45: 30 | L45: =((K45*10)/30) -> 10 | M45: 1 | O45: =SUM(J45,L45,M45) -> 11.6 | P45: =(O45/50)*30 -> 6.96 | Q45: ='Lab Component'!K45 -> 19 | R45: =(P45+Q45) -> 25.96 | S45: =ROUNDUP(R45,0) -> 26
A46: 34 | B46: 1DS22IS034 | C46: BHAVANI C P | D46: 1 | E46: =((D46*30)/50) -> 0.6 | F46: 1 | G46: =((F46*30)/50) -> 0.6 | H46: 1 | I46: =((H46*30)/50) -> 0.6 | J46: =((E46+G46+I46)/3) -> 0.6 | K46: 30 | L46: =((K46*10)/30) -> 10 | M46: 1 | O46: =SUM(J46,L46,M46) -> 11.6 | P46: =(O46/50)*30 -> 6.96 | Q46: ='Lab Component'!K46 -> 20 | R46: =(P46+Q46) -> 26.96 | S46: =ROUNDUP(R46,0) -> 27
... A76: 64 | B76: 1DS22IS064 | C76: JISHNU MANJUNATH M | D76: 1 | E76: =((D76*30)/50) -> 0.6 | F76: 1 | G76: =((F76*30)/50) -> 0.6 | H76: 1 | I76: =((H76*30)/50) -> 0.6 | J76: =((E76+G76+I76)/3) -> 0.6 | K76: 30 | L76: =((K76*10)/30) -> 10 | M76: 1 | O76: =SUM(J76,L76,M76) -> 11.6 | P76: =(O76/50)*30 -> 6.96 | Q76: ='Lab Component'!K76 -> 19 | R76: =(P76+Q76) -> 25.96 | S76: =ROUNDUP(R76,0) -> 26
A77: 65 | B77: 1DS22IS065 | C77: K N RISHAB PURANIKA | D77: 43 | E77: =((D77*30)/50) -> 25.8 | F77: 44 | G77: =((F77*30)/50) -> 26.4 | H77: 46 | I77: =((H77*30)/50) -> 27.6 | J77: =((E77+G77+I77)/3) -> 26.6 | K77: 30 | L77: =((K77*10)/30) -> 10 | M77: 10 | O77: =SUM(J77,L77,M77) -> 46.6 | P77: =(O77/50)*30 -> 27.96 | Q77: ='Lab Component'!K77 -> 20 | R77: =(P77+Q77) -> 47.96 | S77: =ROUNDUP(R77,0) -> 48 | T77: 39
A78: 66 | B78: 1DS22IS066 | C78: KAVYASHREE T | D78: 48 | E78: =((D78*30)/50) -> 28.8 | F78: 50 | G78: =((F78*30)/50) -> 30 | H78: 49 | I78: =((H78*30)/50) -> 29.4 | J78: =((E78+G78+I78)/3) -> 29.4 | K78: 30 | L78: =((K78*10)/30) -> 10 | M78: 10 | O78: =SUM(J78,L78,M78) -> 49.4 | P78: =(O78/50)*30 -> 29.64 | Q78: ='Lab Component'!K78 -> 20 | R78: =(P78+Q78) -> 49.64 | S78: =ROUNDUP(R78,0) -> 50 | T78: 39
A79: 67 | B79: 1DS22IS067 | C79: KEERTHI B | D79: 49 | E79: =((D79*30)/50) -> 29.4 | F79: 50 | G79: =((F79*30)/50) -> 30 | H79: 48 | I79: =((H79*30)/50) -> 28.8 | J79: =((E79+G79+I79)/3) -> 29.4 | K79: 30 | L79: =((K79*10)/30) -> 10 | M79: 8.5 | O79: =SUM(J79,L79,M79) -> 47.9 | P79: =(O79/50)*30 -> 28.74 | Q79: ='Lab Component'!K79 -> 20 | R79: =(P79+Q79) -> 48.74 | S79: =ROUNDUP(R79,0) -> 49 | T79: 39
A80: 68 | B80: 1DS22IS068 | C80: KISHOR KALYANI WADEYAR | D80: 50 | E80: =((D80*30)/50) -> 30 | F80: 47 | G80: =((F80*30)/50) -> 28.2 | H80: 47 | I80: =((H80*30)/50) -> 28.2 | J80: =((E80+G80+I80)/3) -> 28.8 | K80: 30 | L80: =((K80*10)/30) -> 10 | M80: 10 | O80: =SUM(J80,L80,M80) -> 48.8 | P80: =(O80/50)*30 -> 29.28 | Q80: ='Lab Component'!K80 -> 19 | R80: =(P80+Q80) -> 48.28 | S80: =ROUNDUP(R80,0) -> 49 | T80: 37
A81: 69 | B81: 1DS22IS069 | C81: KUSHAL NAYAK S P | D81: 42 | E81: =((D81*30)/50) -> 25.2 | F81: 50 | G81: =((F81*30)/50) -> 30 | H81: 44 | I81: =((H81*30)/50) -> 26.4 | J81: =((E81+G81+I81)/3) -> 27.2 | K81: 30 | L81: =((K81*10)/30) -> 10 | M81: 9.5 | O81: =SUM(J81,L81,M81) -> 46.7 | P81: =(O81/50)*30 -> 28.02 | Q81: ='Lab Component'!K81 -> 19 | R81: =(P81+Q81) -> 47.02 | S81: =ROUNDUP(R81,0) -> 48 | T81: 37
A82: 70 | B82: 1DS22IS070 | C82: LAISIRI N M | D82: 46 | E82: =((D82*30)/50) -> 27.6 | F82: 50 | G82: =((F82*30)/50) -> 30 | H82: 50 | I82: =((H82*30)/50) -> 30 | J82: =((E82+G82+I82)/3) -> 29.2 | K82: 30 | L82: =((K82*10)/30) -> 10 | M82: 10 | O82: =SUM(J82,L82,M82) -> 49.2 | P82: =(O82/50)*30 -> 29.52 | Q82: ='Lab Component'!K82 -> 12 | R82: =(P82+Q82) -> 41.52 | S82: =ROUNDUP(R82,0) -> 42 | T82: 37
A83: 71 | B83: 1DS22IS071 | C83: LANKESH N C D | D83: 40 | E83: =((D83*30)/50) -> 24 | F83: 27 | G83: =((F83*30)/50) -> 16.2 | H83: 43 | I83: =((H83*30)/50) -> 25.8 | J83: =((E83+G83+I83)/3) -> 22 | K83: 30 | L83: =((K83*10)/30) -> 10 | M83: 10 | O83: =SUM(J83,L83,M83) -> 42 | P83: =(O83/50)*30 -> 25.2 | Q83: ='Lab Component'!K83 -> 19 | R83: =(P83+Q83) -> 44.2 | S83: =ROUNDUP(R83,0) -> 45 | T83: 38
...

Sheet Lab Component
C7: CIE for the practical component of Integrated Professional Core Courses (IPCC)
D9: Course
D10: Course Code
C12: Sl. No. | D12: USN | E12: NAME | F12: CIE (30) (H) | G12: Final Test (50) | H12: Final Test Reduced to 20 (I) | I12: Total = H + I (J) | J12: Total out of 50 (J) Marks reduced to 20 (L) | K12: Round up
C13: 1 | D13: 1DS22IS001 | E13: AADARSH KUMAR BATHWAL | F13: =Lab_CIE!P11 -> 29.1 | G13: =Lab_CIA!I11 -> 44 | H13: =((G13*20)/50) -> 17.6 | I13: =SUM(F13,H13) -> 46.7 | J13: =((I13*20)/50) -> 18.68 | K13: =ROUNDUP(J13,0) -> 19
C14: 2 | D14: 1DS22IS002 | E14: AADYA SHRIVASTAVA | F14: =Lab_CIE!P12 -> 29.1 | G14: =Lab_CIA!I12 -> 48 | H14: =((G14*20)/50) -> 19.2 | I14: =SUM(F14,H14) -> 48.3 | J14: =((I14*20)/50) -> 19.32 | K14: =ROUNDUP(J14,0) -> 20
C15: 3 | D15: 1DS22IS003 | E15: ADITHI S PAWAR | F15: =Lab_CIE!P13 -> 29.1 | G15: =Lab_CIA!I13 -> 48 | H15: =((G15*20)/50) -> 19.2 | I15: =SUM(F15,H15) -> 48.3 | J15: =((I15*20)/50) -> 19.32 | K15: =ROUNDUP(J15,0) -> 20
C16: 4 | D16: 1DS22IS004 | E16: ADITHYA N A | F16: =Lab_CIE!P14 -> 28.9 | G16: =Lab_CIA!I14 -> 50 | H16: =((G16*20)/50) -> 20 | I16: =SUM(F16,H16) -> 48.9 | J16: =((I16*20)/50) -> 19.56 | K16: =ROUNDUP(J16,0) -> 20
C17: 5 | D17: 1DS22IS005 | E17: ADITYA ANAND | F17: =Lab_CIE!P15 -> 29 | G17: =Lab_CIA!I15 -> 44 | H17: =((G17*20)/50) -> 17.6 | I17: =SUM(F17,H17) -> 46.6 | J17: =((I17*20)/50) -> 18.64 | K17: =ROUNDUP(J17,0) -> 19
C18: 6 | D18: 1DS22IS006 | E18: ADITYA BHUSHAN | F18: =Lab_CIE!P16 -> 28.2 | G18: =Lab_CIA!I16 -> 48 | H18: =((G18*20)/50) -> 19.2 | I18: =SUM(F18,H18) -> 47.4 | J18: =((I18*20)/50) -> 18.96 | K18: =ROUNDUP(J18,0) -> 19
C19: 7 | D19: 1DS22IS007 | E19: ADITYA GANESH S | F19: =Lab_CIE!P17 -> 28.9 | G19: =Lab_CIA!I17 -> 46 | H19: =((G19*20)/50) -> 18.4 | I19: =SUM(F19,H19) -> 47.3 | J19: =((I19*20)/50) -> 18.92 | K19: =ROUNDUP(J19,0) -> 19
C20: 8 | D20: 1DS22IS008 | E20: ADITYA SINGH | F20: =Lab_CIE!P18 -> 28.9 | G20: =Lab_CIA!I18 -> 48 | H20: =((G20*20)/50) -> 19.2 | I20: =SUM(F20,H20) -> 48.1 | J20: =((I20*20)/50) -> 19.24 | K20: =ROUNDUP(J20,0) -> 20
C21: 9 | D21: 1DS22IS009 | E21: AKASH ARKA B | F21: =Lab_CIE!P19 -> 28.9 | G21: =Lab_CIA!I19 -> 45 | H21: =((G21*20)/50) -> 18 | I21: =SUM(F21,H21) -> 46.9 | J21: =((I21*20)/50) -> 18.76 | K21: =ROUNDUP(J21,0) -> 19
C22: 10 | D22: 1DS22IS010 | E22: AKASH G S | F22: =Lab_CIE!P20 -> 28.8 | G22: =Lab_CIA!I20 -> 48 | H22: =((G22*20)/50) -> 19.2 | I22: =SUM(F22,H22) -> 48 | J22: =((I22*20)/50) -> 19.2 | K22: =ROUNDUP(J22,0) -> 20
C23: 11 | D23: 1DS22IS011 | E23: AKASH GOYAL | F23: =Lab_CIE!P21 -> 28.7 | G23: =Lab_CIA!I21 -> 46 | H23: =((G23*20)/50) -> 18.4 | I23: =SUM(F23,H23) -> 47.1 | J23: =((I23*20)/50) -> 18.84 | K23: =ROUNDUP(J23,0) -> 19
C24: 12 | D24: 1DS22IS012 | E24: AKHAND PRATAP SINGH | F24: =Lab_CIE!P22 -> 28.7 | G24: =Lab_CIA!I22 -> 42 | H24: =((G24*20)/50) -> 16.8 | I24: =SUM(F24,H24) -> 45.5 | J24: =((I24*20)/50) -> 18.2 | K24: =ROUNDUP(J24,0) -> 19
... C219: 207 | D219: 1DS23IS417 | E219: VILESH RAJATH G V | F219: =Lab_CIE!P217 -> 28.6 | G219: =Lab_CIA!I217 -> 37 | H219: =((G219*20)/50) -> 14.8 | I219: =SUM(F219,H219) -> 43.4 | J219: =((I219*20)/50) -> 17.36 | K219: =ROUNDUP(J219,0) -> 18

Sheet Lab_CIE
C6: DIGITAL LOGIC DESIGN LABORATORY -IPCC22IS33
C7: CIE MARKS - 2024-25
D8: SEM: 3
C10: Sl. No. | D10: USN | E10: NAME | F10: EXP 1 | G10: EXP 2 | H10: EXP 3 | I10: EXP 4 | J10: EXP 5 | K10: EXP 6 | L10: EXP 7 | M10: EXP 8 | N10: EXP 9 | O10: EXP 10 | P10: AVG(30)
C11: 1 | D11: 1DS22IS001 | E11: AADARSH KUMAR BATHWAL | F11: 28 | G11: 29 | H11: 29 | I11: 29 | J11: 30 | K11: 29 | L11: 29 | M11: 30 | N11: 29 | O11: 29 | P11: =AVERAGE(F11:O11) -> 29.1
C12: 2 | D12: 1DS22IS002 | E12: AADYA SHRIVASTAVA | F12: 30 | G12: 28 | H12: 28 | I12: 29 | J12: 30 | K12: 29 | L12: 29 | M12: 30 | N12: 29 | O12: 29 | P12: =AVERAGE(F12:O12) -> 29.1
C13: 3 | D13: 1DS22IS003 | E13: ADITHI S PAWAR | F13: 30 | G13: 28 | H13: 29 | I13: 29 | J13: 30 | K13: 28 | L13: 29 | M13: 30 | N13: 29 | O13: 29 | P13: =AVERAGE(F13:O13) -> 29.1
C14: 4 | D14: 1DS22IS004 | E14: ADITHYA N A | F14: 29 | G14: 28 | H14: 29 | I14: 28 | J14: 30 | K14: 28 | L14: 29 | M14: 30 | N14: 29 | O14: 29 | P14: =AVERAGE(F14:O14) -> 28.9
C15: 5 | D15: 1DS22IS005 | E15: ADITYA ANAND | F15: 29 | G15: 29 | H15: 29 | I15: 28 | J15: 30 | K15: 29 | L15: 29 | M15: 29 | N15: 29 | O15: 29 | P15: =AVERAGE(F15:O15) -> 29
C16: 6 | D16: 1DS22IS006 | E16: ADITYA BHUSHAN | F16: 27 | G16: 27 | H16: 27 | I16: 28 | J16: 30 | K16: 29 | L16: 28 | M16: 29 | N16: 28 | O16: 29 | P16: =AVERAGE(F16:O16) -> 28.2
C17: 7 | D17: 1DS22IS007 | E17: ADITYA GANESH S | F17: 29 | G17: 29 | H17: 29 | I17: 29 | J17: 30 | K17: 29 | L17: 28 | M17: 29 | N17: 28 | O17: 29 | P17: =AVERAGE(F17:O17) -> 28.9
C18: 8 | D18: 1DS22IS008 | E18: ADITYA SINGH | F18: 29 | G18: 28 | H18: 29 | I18: 29 | J18: 30 | K18: 29 | L18: 28 | M18: 29 | N18: 29 | O18: 29 | P18: =AVERAGE(F18:O18) -> 28.9
C19: 9 | D19: 1DS22IS009 | E19: AKASH ARKA B | F19: 28 | G19: 28 | H19: 29 | I19: 29 | J19: 30 | K19: 29 | L19: 29 | M19: 29 | N19: 29 | O19: 29 | P19: =AVERAGE(F19:O19) -> 28.9
C20: 10 | D20: 1DS22IS010 | E20: AKASH G S | F20: 29 | G20: 28 | H20: 29 | I20: 29 | J20: 30 | K20: 29 | L20: 29 | M20: 29 | N20: 28 | O20: 28 | P20: =AVERAGE(F20:O20) -> 28.8
C21: 11 | D21: 1DS22IS011 | E21: AKASH GOYAL | F21: 28 | G21: 28 | H21: 29 | I21: 29 | J21: 30 | K21: 28 | L21: 29 | M21: 30 | N21: 28 | O21: 28 | P21: =AVERAGE(F21:O21) -> 28.7
C22: 12 | D22: 1DS22IS012 | E22: AKHAND PRATAP SINGH | F22: 28 | G22: 28 | H22: 29 | I22: 29 | J22: 30 | K22: 28 | L22: 28 | M22: 30 | N22: 28 | O22: 29 | P22: =AVERAGE(F22:O22) -> 28.7
... C90: 80 | D90: 1DS22IS081 | E90: MANOJ N | F90: 28 | G90: 29 | H90: 29 | I90: 27 | J90: 28 | K90: 29 | L90: 29 | M90: 27 | N90: 28 | O90: 29 | P90: =AVERAGE(F90:O90) -> 28.3
C91: 81 | D91: 1DS22IS082 | E91: MAYUR ADARSH N S | N91: 26 | O91: 27 | P91: =AVERAGE(F91:O91) -> 26.5
C92: 82 | D92: 1DS22IS083 | E92: MD NADEEM | F92: 29 | G92: 29 | H92: 30 | I92: 27 | J92: 29 | K92: 29 | L92: 30 | M92: 27 | N92: 25 | O92: 25 | P92: =AVERAGE(F92:O92) -> 28
C93: 83 | D93: 1DS22IS084 | E93: MITHUN A M | F93: 30 | G93: 30 | H93: 30 | I93: 27 | J93: 30 | K93: 30 | L93: 30 | M93: 27 | N93: 30 | O93: 29 | P93: =AVERAGE(F93:O93) -> 29.3
C94: 84 | D94: 1DS22IS085 | E94: MIZBA ULLAIN | F94: 28 | G94: 27 | H94: 27 | I94: 28 | J94: 28 | K94: 27 | L94: 27 | M94: 28 | N94: 24 | O94: 24 | P94: =AVERAGE(F94:O94) -> 26.8
C95: 85 | D95: 1DS22IS086 | E95: MOHAMMED FARHAN KHAN | F95: 27 | G95: 27 | H95: 26 | I95: 26 | J95: 27 | K95: 27 | L95: 26 | M95: 26 | N95: 26 | O95: 25 | P95: =AVERAGE(F95:O95) -> 26.3
C96: 86 | D96: 1DS22IS087 | E96: MOHAMMED IDREES | F96: 28 | G96: 28 | H96: 26 | I96: 26 | J96: 26 | K96: 28 | L96: 30 | M96: 30 | N96: 30 | O96: 30 | P96: =AVERAGE(F96:O96) -> 28.2
C97: 87 | D97: 1DS22IS088 | E97: MOHAMMED UZAIR | F97: 28 | G97: 28 | H97: 26 | I97: 26 | J97: 28 | K97: 28 | L97: 30 | M97: 30 | N97: 30 | O97: 30 | P97: =AVERAGE(F97:O97) -> 28.4
C98: 88 | D98: 1DS22IS089 | E98: MOKSHITH R D | F98: 29 | G98: 29 | H98: 30 | I98: 27 | J98: 28 | K98: 28 | L98: 30 | M98: 30 | N98: 30 | O98: 30 | P98: =AVERAGE(F98:O98) -> 29.1
C99: 89 | D99: 1DS22IS090 | E99: MUMMADI D L NARASIMHA REDDY | F99: 29 | G99: 29 | H99: 28 | I99: 27 | J99: 28 | K99: 28 | L99: 30 | M99: 30 | N99: 30 | O99: 30 | P99: =AVERAGE(F99:O99) -> 28.9
C100: 90 | D100: 1DS22IS091 | E100: NAGARAJ | F100: 29 | G100: 29 | H100: 28 | I100: 27 | J100: 28 | K100: 28 | L100: 30 | M100: 30 | N100: 30 | O100: 30 | P100: =AVERAGE(F100:O100) -> 28.9
C101: 91 | D101: 1DS22IS092 | E101: NAVDEEP C | F101: 27 | G101: 29 | H101: 28 | I101: 27 | J101: 28 | K101: 28 | L101: 30 | M101: 30 | N101: 30 | O101: 30 | P101: =AVERAGE(F101:O101) -> 28.7
C102: 92 | D102: 1DS22IS093 | E102: NAVNEET G SATWIK | F102: 30 | G102: 30 | H102: 29 | I102: 29 | J102: 28 | K102: 28 | L102: 30 | M102: 30 | N102: 30 | O102: 30 | P102: =AVERAGE(F102:O102) -> 29.4
C103: 93 | D103: 1DS22IS094 | E103: NAVYA V S | P103: =AVERAGE(F103:O103) -> #DIV/0!
C104: 94 | D104: 1DS22IS095 | E104: NIDHA HUSSAIN | F104: 30 | G104: 30 | H104: 30 | I104: 30 | J104: 28 | K104: 28 | L104: 30 | M104: 30 | N104: 30 | O104: 30 | P104: =AVERAGE(F104:O104) -> 29.6
C105: 95 | D105: 1DS22IS096 | E105: NIDHI RAJIV | F105: 30 | G105: 30 | H105: 30 | I105: 30 | J105: 28 | K105: 28 | L105: 30 | M105: 30 | N105: 30 | O105: 30 | P105: =AVERAGE(F105:O105) -> 29.6
C106: 96 | D106: 1DS22IS097 | E106: NIHARIKA N | F106: 30 | G106: 30 | H106: 30 | I106: 30 | J106: 28 | K106: 28 | L106: 30 | M106: 30 | N106: 30 | O106: 30 | P106: =AVERAGE(F106:O106) -> 29.6
C107: 97 | D107: 1DS22IS098 | E107: NIKHIL CHANDRAKANT KAMANNAVAR | F107: 30 | G107: 30 | H107: 30 | I107: 30 | J107: 28 | K107: 28 | L107: 30 | M107: 30 | N107: 30 | O107: 30 | P107: =AVERAGE(F107:O107) -> 29.6
C108: 98 | D108: 1DS22IS099 | E108: NITHIN RAJ H | F108: 30 | G108: 30 | H108: 30 | I108: 30 | J108: 28 | K108: 28 | L108: 30 | M108: 30 | N108: 30 | O108: 30 | P108: =AVERAGE(F108:O108) -> 29.6
C109: 99 | D109: 1DS22IS100 | E109: NITINRAJ GAMPA | F109: 30 | G109: 30 | H109: 30 | I109: 30 | J109: 28 | K109: 28 | L109: 30 | M109: 30 | N109: 30 | O109: 30 | P109: =AVERAGE(F109:O109) -> 29.6
C110: 100 | D110: 1DS22IS101 | E110: PALLAVI K | F110: 30 | G110: 30 | H110: 30 | I110: 30 | J110: 30 | K110: 30 | L110: 28 | M110: 28 | N110: 30 | O110: 30 | P110: =AVERAGE(F110:O110) -> 29.6
C111: 101 | D111: 1DS22IS102 | E111: PALLAVI P KAMATH | F111: 30 | G111: 30 | H111: 30 | I111: 30 | J111: 30 | K111: 30 | L111: 28 | M111: 30 | N111: 30 | O111: 30 | P111: =AVERAGE(F111:O111) -> 29.8
C112: 102 | D112: 1DS22IS103 | E112: PARINEETHA M | F112: 28 | G112: 30 | H112: 28 | I112: 30 | J112: 30 | K112: 30 | L112: 28 | M112: 28 | N112: 30 | O112: 30 | P112: =AVERAGE(F112:O112) -> 29.2
C113: 103 | D113: 1DS22IS104 | E113: PAVAN RAIKAR | F113: 30 | G113: 30 | H113: 30 | I113: 30 | J113: 28 | K113: 28 | L113: 28 | M113: 30 | N113: 30 | O113: 30 | P113: =AVERAGE(F113:O113) -> 29.4
...

Sheet Lab_CIA
C6: DIGITAL LOGIC DESIGN LABORATORY -IPCC22IS33
C7: CIA MARKS - 2024-25
D8: SEM: 3
C10: Sl. No. | D10: USN | E10: NAME | F10: WRITE-UP(08) | G10: EXECUTION(35) | H10: VIVA(07) | I10: TOTAL(50) | J10: TOTAL(20)
C11: 1 | D11: 1DS22IS001 | E11: AADARSH KUMAR BATHWAL | F11: 8 | G11: 30 | H11: 6 | I11: =SUM(F11:H11) -> 44 | J11: =I11*0.4 -> 17.6
C12: 2 | D12: 1DS22IS002 | E12: AADYA SHRIVASTAVA | F12: 8 | G12: 34 | H12: 6 | I12: =SUM(F12:H12) -> 48 | J12: =I12*0.4 -> 19.2
C13: 3 | D13: 1DS22IS003 | E13: ADITHI S PAWAR | F13: 8 | G13: 34 | H13: 6 | I13: =SUM(F13:H13) -> 48 | J13: =I13*0.4 -> 19.2
C14: 4 | D14: 1DS22IS004 | E14: ADITHYA N A | F14: 8 | G14: 35 | H14: 7 | I14: =SUM(F14:H14) -> 50 | J14: =I14*0.4 -> 20
C15: 5 | D15: 1DS22IS005 | E15: ADITYA ANAND | F15: 8 | G15: 32 | H15: 4 | I15: =SUM(F15:H15) -> 44 | J15: =I15*0.4 -> 17.6
C16: 6 | D16: 1DS22IS006 | E16: ADITYA BHUSHAN | F16: 8 | G16: 34 | H16: 6 | I16: =SUM(F16:H16) -> 48 | J16: =I16*0.4 -> 19.2
C17: 7 | D17: 1DS22IS007 | E17: ADITYA GANESH S | F17: 8 | G17: 33 | H17: 5 | I17: =SUM(F17:H17) -> 46 | J17: =I17*0.4 -> 18.4
C18: 8 | D18: 1DS22IS008 | E18: ADITYA SINGH | F18: 8 | G18: 34 | H18: 6 | I18: =SUM(F18:H18) -> 48 | J18: =I18*0.4 -> 19.2
C19: 9 | D19: 1DS22IS009 | E19: AKASH ARKA B | F19: 4 | G19: 35 | H19: 6 | I19: =SUM(F19:H19) -> 45 | J19: =I19*0.4 -> 18
C20: 10 | D20: 1DS22IS010 | E20: AKASH G S | F20: 8 | G20: 34 | H20: 6 | I20: =SUM(F20:H20) -> 48 | J20: =I20*0.4 -> 19.2
C21: 11 | D21: 1DS22IS011 | E21: AKASH GOYAL | F21: 8 | G21: 33 | H21: 5 | I21: =SUM(F21:H21) -> 46 | J21: =I21*0.4 -> 18.4
C22: 12 | D22: 1DS22IS012 | E22: AKHAND PRATAP SINGH | F22: 8 | G22: 30 | H22: 4 | I22: =SUM(F22:H22) -> 42 | J22: =I22*0.4 -> 16.8
... C79: 69 | D79: 1DS22IS069 | E79: KUSHAL NAYAK S P | F79: 5 | G79: 32 | H79: 5 | I79: =SUM(F79:H79) -> 42 | J79: =I79*0.4 -> 16.8
C80: 70 | D80: 1DS22IS070 | E80: LAISIRI N M | I80: =SUM(F80:H80) -> 0 | J80: =I80*0.4 -> 0
C81: 71 | D81: 1DS22IS071 | E81: LANKESH N C D | F81: 6 | G81: 33 | H81: 6 | I81: =SUM(F81:H81) -> 45 | J81: =I81*0.4 -> 18
C82: 72 | D82: 1DS22IS072 | E82: LIKITH S | F82: 5 | G82: 30 | H82: 3 | I82: =SUM(F82:H82) -> 38 | J82: =I82*0.4 -> 15.2
C83: 73 | D83: 1DS22IS073 | E83: LOCHAN T N | I83: =SUM(F83:H83) -> 0 | J83: =I83*0.4 -> 0
C84: 74 | D84: 1DS22IS074 | E84: M R NISHANTH | F84: 7 | G84: 33 | H84: 5 | I84: =SUM(F84:H84) -> 45 | J84: =I84*0.4 -> 18
C85: 75 | D85: 1DS22IS075 | E85: MADHU R | F85: 6 | G85: 34 | H85: 5 | I85: =SUM(F85:H85) -> 45 | J85: =I85*0.4 -> 18
C86: 76 | D86: 1DS22IS076 | E86: MALIAKA SARA DRABOO | I86: =SUM(F86:H86) -> 0 | J86: =I86*0.4 -> 0
C87: 77 | D87: 1DS22IS077 | E87: MANASWINI G | I87: =SUM(F87:H87) -> 0 | J87: =I87*0.4 -> 0
C88: 78 | D88: 1DS22IS078 | E88: MANDAN MISHRA | F88: 7 | G88: 33 | H88: 6 | I88: =SUM(F88:H88) -> 46 | J88: =I88*0.4 -> 18.4
C89: 79 | D89: 1DS22IS080 | E89: MANISH S SHETTY | F89: 6 | G89: 32 | H89: 6 | I89: =SUM(F89:H89) -> 44 | J89: =I89*0.4 -> 17.6
C90: 80 | D90: 1DS22IS081 | E90: MANOJ N | F90: 7 | G90: 33 | H90: 7 | I90: =SUM(F90:H90) -> 47 | J90: =I90*0.4 -> 18.8
C91: 81 | D91: 1DS22IS082 | E91: MAYUR ADARSH N S | I91: =SUM(F91:H91) -> 0 | J91: =I91*0.4 -> 0
C92: 82 | D92: 1DS22IS083 | E92: MD NADEEM | F92: 7 | G92: 33 | H92: 5 | I92: =SUM(F92:H92) -> 45 | J92: =I92*0.4 -> 18
C93: 83 | D93: 1DS22IS084 | E93: MITHUN A M | F93: 8 | G93: 35 | H93: 6 | I93: =SUM(F93:H93) -> 49 | J93: =I93*0.4 -> 19.6
C94: 84 | D94: 1DS22IS085 | E94: MIZBA ULLAIN | F94: 5 | G94: 30 | H94: 5 | I94: =SUM(F94:H94) -> 40 | J94: =I94*0.4 -> 16
C95: 85 | D95: 1DS22IS086 | E95: MOHAMMED FARHAN KHAN | F95: 6 | G95: 34 | H95: 6 | I95: =SUM(F95:H95) -> 46 | J95: =I95*0.4 -> 18.4
C96: 86 | D96: 1DS22IS087 | E96: MOHAMMED IDREES | F96: 6 | G96: 32 | H96: 6 | I96: =SUM(F96:H96) -> 44 | J96: =I96*0.4 -> 17.6
C97: 87 | D97: 1DS22IS088 | E97: MOHAMMED UZAIR | F97: 8 | G97: 35 | H97: 7 | I97: =SUM(F97:H97) -> 50 | J97: =I97*0.4 -> 20
C98: 88 | D98: 1DS22IS089 | E98: MOKSHITH R D | F98: 6 | G98: 34 | H98: 4 | I98: =SUM(F98:H98) -> 44 | J98: =I98*0.4 -> 17.6
C99: 89 | D99: 1DS22IS090 | E99: MUMMADI D L NARASIMHA REDDY | F99: 4 | G99: 32 | H99: 4 | I99: =SUM(F99:H99) -> 40 | J99: =I99*0.4 -> 16
C100: 90 | D100: 1DS22IS091 | E100: NAGARAJ | F100: 6 | G100: 32 | H100: 5 | I100: =SUM(F100:H100) -> 43 | J100: =I100*0.4 -> 17.2
C101: 91 | D101: 1DS22IS092 | E101: NAVDEEP C | F101: 8 | G101: 35 | H101: 6 | I101: =SUM(F101:H101) -> 49 | J101: =I101*0.4 -> 19.6
C102: 92 | D102: 1DS22IS093 | E102: NAVNEET G SATWIK | F102: 5 | G102: 32 | H102: 4 | I102: =SUM(F102:H102) -> 41 | J102: =I102*0.4 -> 16.4
...

Sheet CIE+CIA
C6: DIGITAL LOGIC DESIGN LABORATORY -IPCC22IS33
C7: INTERNAL MARKS - 2024-25
D8: SEM: 6
D9: SECTION: A, B, C
C10: Sl. No. | D10: USN | E10: NAME | F10: CIE(30) | G10: CIA(20) | H10: TOTAL(50)
C11: 1 | D11: 1DS22IS001 | E11: AADARSH KUMAR BATHWAL | F11: =Lab_CIE!P11 -> 29.1 | G11: =Lab_CIA!J11 -> 17.6 | H11: =F11+G11 -> 46.7
C12: 2 | D12: 1DS22IS002 | E12: AADYA SHRIVASTAVA | F12: =Lab_CIE!P12 -> 29.1 | G12: =Lab_CIA!J12 -> 19.2 | H12: =F12+G12 -> 48.3
C13: 3 | D13: 1DS22IS003 | E13: ADITHI S PAWAR | F13: =Lab_CIE!P13 -> 29.1 | G13: =Lab_CIA!J13 -> 19.2 | H13: =F13+G13 -> 48.3
C14: 4 | D14: 1DS22IS004 | E14: ADITHYA N A | F14: =Lab_CIE!P14 -> 28.9 | G14: =Lab_CIA!J14 -> 20 | H14: =F14+G14 -> 48.9
C15: 5 | D15: 1DS22IS005 | E15: ADITYA ANAND | F15: =Lab_CIE!P15 -> 29 | G15: =Lab_CIA!J15 -> 17.6 | H15: =F15+G15 -> 46.6
C16: 6 | D16: 1DS22IS006 | E16: ADITYA BHUSHAN | F16: =Lab_CIE!P16 -> 28.2 | G16: =Lab_CIA!J16 -> 19.2 | H16: =F16+G16 -> 47.4
C17: 7 | D17: 1DS22IS007 | E17: ADITYA GANESH S | F17: =Lab_CIE!P17 -> 28.9 | G17: =Lab_CIA!J17 -> 18.4 | H17: =F17+G17 -> 47.3
C18: 8 | D18: 1DS22IS008 | E18: ADITYA SINGH | F18: =Lab_CIE!P18 -> 28.9 | G18: =Lab_CIA!J18 -> 19.2 | H18: =F18+G18 -> 48.1
C19: 9 | D19: 1DS22IS009 | E19: AKASH ARKA B | F19: =Lab_CIE!P19 -> 28.9 | G19: =Lab_CIA!J19 -> 18 | H19: =F19+G19 -> 46.9
C20: 10 | D20: 1DS22IS010 | E20: AKASH G S | F20: =Lab_CIE!P20 -> 28.8 | G20: =Lab_CIA!J20 -> 19.2 | H20: =F20+G20 -> 48
C21: 11 | D21: 1DS22IS011 | E21: AKASH GOYAL | F21: =Lab_CIE!P21 -> 28.7 | G21: =Lab_CIA!J21 -> 18.4 | H21: =F21+G21 -> 47.1
C22: 12 | D22: 1DS22IS012 | E22: AKHAND PRATAP SINGH | F22: =Lab_CIE!P22 -> 28.7 | G22: =Lab_CIA!J22 -> 16.8 | H22: =F22+G22 -> 45.5
... C217: 207 | D217: 1DS23IS417 | E217: VILESH RAJATH G V | F217: =Lab_CIE!P217 -> 28.6 | G217: =Lab_CIA!J217 -> 14.8 | H217: =F217+G217 -> 43.4

Sheet TOTAL
C6: DIGITAL LOGIC DESIGN LABORATORY -IPCC22IS33
C7: FINAL MARKS -2024-25
D8: SEM: 3
D9: SECTION: A, B, C
C10: Sl. No. | D10: USN | E10: NAME | F10: TOTAL(50) | G10: FINAL(20) | H10: FINAL-RoundUp
C11: 1 | D11: 1DS22IS001 | E11: AADARSH KUMAR BATHWAL | F11: ='CIE+CIA'!H11 -> 46.7 | G11: =F11*0.4 -> 18.68 | H11: =ROUNDUP(G11,0) -> 19
C12: 2 | D12: 1DS22IS002 | E12: AADYA SHRIVASTAVA | F12: ='CIE+CIA'!H12 -> 48.3 | G12: =F12*0.4 -> 19.32 | H12: =ROUNDUP(G12,0) -> 20
C13: 3 | D13: 1DS22IS003 | E13: ADITHI S PAWAR | F13: ='CIE+CIA'!H13 -> 48.3 | G13: =F13*0.4 -> 19.32 | H13: =ROUNDUP(G13,0) -> 20
C14: 4 | D14: 1DS22IS004 | E14: ADITHYA N A | F14: ='CIE+CIA'!H14 -> 48.9 | G14: =F14*0.4 -> 19.56 | H14: =ROUNDUP(G14,0) -> 20
C15: 5 | D15: 1DS22IS005 | E15: ADITYA ANAND | F15: ='CIE+CIA'!H15 -> 46.6 | G15: =F15*0.4 -> 18.64 | H15: =ROUNDUP(G15,0) -> 19
C16: 6 | D16: 1DS22IS006 | E16: ADITYA BHUSHAN | F16: ='CIE+CIA'!H16 -> 47.4 | G16: =F16*0.4 -> 18.96 | H16: =ROUNDUP(G16,0) -> 19
C17: 7 | D17: 1DS22IS007 | E17: ADITYA GANESH S | F17: ='CIE+CIA'!H17 -> 47.3 | G17: =F17*0.4 -> 18.92 | H17: =ROUNDUP(G17,0) -> 19
C18: 8 | D18: 1DS22IS008 | E18: ADITYA SINGH | F18: ='CIE+CIA'!H18 -> 48.1 | G18: =F18*0.4 -> 19.24 | H18: =ROUNDUP(G18,0) -> 20
C19: 9 | D19: 1DS22IS009 | E19: AKASH ARKA B | F19: ='CIE+CIA'!H19 -> 46.9 | G19: =F19*0.4 -> 18.76 | H19: =ROUNDUP(G19,0) -> 19
C20: 10 | D20: 1DS22IS010 | E20: AKASH G S | F20: ='CIE+CIA'!H20 -> 48 | G20: =F20*0.4 -> 19.2 | H20: =ROUNDUP(G20,0) -> 20
C21: 11 | D21: 1DS22IS011 | E21: AKASH GOYAL | F21: ='CIE+CIA'!H21 -> 47.1 | G21: =F21*0.4 -> 18.84 | H21: =ROUNDUP(G21,0) -> 19
C22: 12 | D22: 1DS22IS012 | E22: AKHAND PRATAP SINGH | F22: ='CIE+CIA'!H22 -> 45.5 | G22: =F22*0.4 -> 18.2 | H22: =ROUNDUP(G22,0) -> 19
... C217: 207 | D217: 1DS23IS417 | E217: VILESH RAJATH G V | F217: ='CIE+CIA'!H217 -> 43.4 | G217: =F217*0.4 -> 17.36 | H217: =ROUNDUP(G217,0) -> 18

Sheet ATTENDANCE
A1: Sl. No. | B1: USN | C1: NAME | D1: ATTENDANCE(12)
A2: 1 | B2: 1DS22IS001 | C2: AADARSH KUMAR BATHWAL | D2: 11
A3: 2 | B3: 1DS22IS002 | C3: AADYA SHRIVASTAVA | D3: 11
A4: 3 | B4: 1DS22IS003 | C4: ADITHI S PAWAR | D4: 12
A5: 4 | B5: 1DS22IS004 | C5: ADITHYA N A | D5: 12
A6: 5 | B6: 1DS22IS005 | C6: ADITYA ANAND | D6: 11
A7: 6 | B7: 1DS22IS006 | C7: ADITYA BHUSHAN | D7: 11
A8: 7 | B8: 1DS22IS007 | C8: ADITYA GANESH S | D8: 12
A9: 8 | B9: 1DS22IS008 | C9: ADITYA SINGH | D9: 11
A10: 9 | B10: 1DS22IS009 | C10: AKASH ARKA B | D10: 11
A11: 10 | B11: 1DS22IS010 | C11: AKASH G S | D11: 12
A12: 11 | B12: 1DS22IS011 | C12: AKASH GOYAL | D12: 12
A13: 12 | B13: 1DS22IS012 | C13: AKHAND PRATAP SINGH | D13: 11
... A192: 191 | B192: 1DS23IS401 | C192: BALAJI B N | D192: 12
A193: 192 | B193: 1DS23IS402 | C193: CHETHAN G
A194: 193 | B194: 1DS23IS403 | C194: DAYANAND BADIGER | D194: 12
A195: 194 | B195: 1DS23IS404 | C195: DEERAJ GANESH M | D195: 11
A196: 195 | B196: 1DS23IS405 | C196: G C RAKESH | D196: 12
A197: 196 | B197: 1DS23IS406 | C197: HAMSA G | D197: 12
A198: 197 | B198: 1DS23IS407 | C198: HIMANSHU B A
A199: 198 | B199: 1DS23IS408 | C199: KARTIK B PATIL
A200: 199 | B200: 1DS23IS409 | C200: MANJIT JITENDRA SAWANT
A201: 200 | B201: 1DS23IS410 | C201: MANJUNATH S | D201: 12
A202: 201 | B202: 1DS23IS411 | C202: MANOJ S | D202: 12
A203: 202 | B203: 1DS23IS412 | C203: NEEHA FATHIMA | D203: 12
A204: 203 | B204: 1DS23IS413 | C204: NITHISH M | D204: 12
A205: 204 | B205: 1DS23IS414 | C205: NITIN KUMAR | D205: 12
A206: 205 | B206: 1DS23IS415 | C206: PRASHANT S NAGANI | D206: 11
A207: 206 | B207: 1DS23IS416 | C207: VIKAS D H | D207: 11
A208: 207 | B208: 1DS23IS417 | C208: VILESH RAJATH G V | D208: 12
A209: 208 | B209: 24UGDS0590 | C209: VEERGANGADHAR B HIREMATH | D209: 12
A210: 209 | B210: 24UGDS0541 | C210: VENKATESH H D | D210: 12

Sheet Sheet3
A1: Row Labels | B1: Count of USN
A2: 4 | B2: 1
A3: 35 | B3: 3
A4: 37 | B4: 2
A5: 38 | B5: 5
A6: 39 | B6: 2
A7: 40 | B7: 2
A8: 41 | B8: 2
A9: 42 | B9: 3
A10: 43 | B10: 3
A11: 44 | B11: 8
A12: 45 | B12: 5
A13: 46 | B13: 10
... A17: 50 | B17: 1
A18: Grand Total | B18: 68

Sheet C_Section_Marks
A1: Sl. No | B1: USN | C1: Total Marks
A2: 129 | B2: 1DS22IS129 | C2: 44
A3: 130 | B3: 1DS22IS130 | C3: 49
A4: 131 | B4: 1DS22IS131 | C4: 44
A5: 132 | B5: 1DS22IS132 | C5: 38
A6: 133 | B6: 1DS22IS133 | C6: 46
A7: 134 | B7: 1DS22IS134 | C7: 4
A8: 135 | B8: 1DS22IS135 | C8: 37
A9: 136 | B9: 1DS22IS136 | C9: 42
A10: 137 | B10: 1DS22IS137 | C10: 45
A11: 138 | B11: 1DS22IS138 | C11: 49
A12: 139 | B12: 1DS22IS139 | C12: 48
A13: 140 | B13: 1DS22IS140 | C13: 43
... A69: 207 | B69: 1DS23IS417 | C69: 39

Sheet Sheet2
